Workbook

Sheet PLANILLA PARA MATERIA
A1: MINISTERIO DE EDUCACIÓN | D1: AÑO: 2026 | Y1: DIRECCION NACIONAL DE EVALUACION E INVESTIGACION
A2: DIRECCION NACIONAL DE EDUCACION | F2: INSTITUTO NACIONAL DE SANTIAGO DE MARIA (INSAM)
C3: CUADRO DE REGISTRO DE EVALUACION DE LOS APRENDIZAJES
J4: POR ASIGNATURA Y PERIODOS
A5: EDUCACION MEDIA: 1° T.V. EN DESARROLLO DE SOFTWARE | F5: SECCIÓN: | H5: " B " | O5: materia | Q5: ESTUDIOS SOCIALES | X5: Profesor: | AA5: LIDIA CONCEPCION GONZALEZ DE CABALLERO | AJ5: Grado
D6: GE | F6: Primer Periodo | M6: Segundo Período | T6: Tercer Período | AA6: Cuarto Período | AG6: Pro- | AH6: Pro- | AI6: Nota | AJ6: Nota
A7: Nº | B7: NIE | C7: NOMBRE DEL ALUMNO/A | D7: NE | F7: Actividades | K7: Pro- | M7: Actividades | R7: Pro- | T7: Actividades | Y7: Pro- | AA7: Actividades | AF7: Pro- | AG7: me- | AH7: me- | AI7: Recu- | AJ7: Final | AK7: Observaciones
D8: RO | F8: 1 | H8: 2 | J8: 3 | K8: me- | M8: 1 | O8: 2 | Q8: 3 | R8: me- | T8: 1 | V8: 2 | X8: 3 | Y8: me- | AA8: 1 | AC8: 2 | AE8: 3 | AF8: me- | AG8: dio | AH8: dio | AI8: pera- | AJ8: conso
F9: 0.35 | H9: 0.35 | J9: 0.3 | K9: dio | M9: 0.35 | O9: 0.35 | Q9: 0.3 | R9: dio | T9: 0.35 | V9: 0.35 | X9: 0.3 | Y9: dio | AA9: 0.35 | AC9: 0.35 | AE9: 0.3 | AF9: dio | AG9: Inst. | AH9: Final | AI9: ción | AJ9: lidada
A10: 1 | D10: F | F10: =E10*35% -> 0 | H10: =G10*35% -> 0 | J10: =I10*30% -> 0 | K10: =ROUND((F10+H10+J10),2) -> 0 | M10: =L10*35% -> 0 | O10: =N10*35% -> 0 | Q10: =P10*30% -> 0 | R10: =ROUND((M10+O10+Q10),2) -> 0 | T10: =S10*35% -> 0 | V10: =U10*35% -> 0 | X10: =W10*30% -> 0 | Y10: =ROUND((T10+V10+X10),2) -> 0 | AA10: =Z10*35% -> 0 | AC10: =AB10*35% -> 0 | AE10: =AD10*30% -> 0 | AF10: =ROUND((AA10+AC10+AE10),2) -> 0 | AG10: =VALUE((K10+R10+Y10+AF10)/4) -> 0 | AH10: =ROUND(AG10,1) -> 0 | AJ10: =IF(AI10<=0,AH10,(AH10+AI10)/2) -> 0
A11: 2 | D11: M | F11: =E11*35% -> 0 | H11: =G11*35% -> 0 | J11: =I11*30% -> 0 | K11: =ROUND((F11+H11+J11),2) -> 0 | M11: =L11*35% -> 0 | O11: =N11*35% -> 0 | Q11: =P11*30% -> 0 | R11: =ROUND((M11+O11+Q11),2) -> 0 | T11: =S11*35% -> 0 | V11: =U11*35% -> 0 | X11: =W11*30% -> 0 | Y11: =ROUND((T11+V11+X11),2) -> 0 | AA11: =Z11*35% -> 0 | AC11: =AB11*35% -> 0 | AE11: =AD11*30% -> 0 | AF11: =ROUND((AA11+AC11+AE11),2) -> 0 | AG11: =VALUE((K11+R11+Y11+AF11)/4) -> 0 | AH11: =ROUND(AG11,1) -> 0 | AJ11: =IF(AI11<=0,AH11,(AH11+AI11)/2) -> 0
A12: 3 | D12: M | F12: =E12*35% -> 0 | H12: =G12*35% -> 0 | J12: =I12*30% -> 0 | K12: =ROUND((F12+H12+J12),2) -> 0 | M12: =L12*35% -> 0 | O12: =N12*35% -> 0 | Q12: =P12*30% -> 0 | R12: =ROUND((M12+O12+Q12),2) -> 0 | T12: =S12*35% -> 0 | V12: =U12*35% -> 0 | X12: =W12*30% -> 0 | Y12: =ROUND((T12+V12+X12),2) -> 0 | AA12: =Z12*35% -> 0 | AC12: =AB12*35% -> 0 | AE12: =AD12*30% -> 0 | AF12: =ROUND((AA12+AC12+AE12),2) -> 0 | AG12: =VALUE((K12+R12+Y12+AF12)/4) -> 0 | AH12: =ROUND(AG12,1) -> 0 | AJ12: =IF(AI12<=0,AH12,(AH12+AI12)/2) -> 0
A13: 4 | D13: F | F13: =E13*35% -> 0 | H13: =G13*35% -> 0 | J13: =I13*30% -> 0 | K13: =ROUND((F13+H13+J13),2) -> 0 | M13: =L13*35% -> 0 | O13: =N13*35% -> 0 | Q13: =P13*30% -> 0 | R13: =ROUND((M13+O13+Q13),2) -> 0 | T13: =S13*35% -> 0 | V13: =U13*35% -> 0 | X13: =W13*30% -> 0 | Y13: =ROUND((T13+V13+X13),2) -> 0 | AA13: =Z13*35% -> 0 | AC13: =AB13*35% -> 0 | AE13: =AD13*30% -> 0 | AF13: =ROUND((AA13+AC13+AE13),2) -> 0 | AG13: =VALUE((K13+R13+Y13+AF13)/4) -> 0 | AH13: =ROUND(AG13,1) -> 0 | AJ13: =IF(AI13<=0,AH13,(AH13+AI13)/2) -> 0
A14: 5 | D14: F | F14: =E14*35% -> 0 | H14: =G14*35% -> 0 | J14: =I14*30% -> 0 | K14: =ROUND((F14+H14+J14),2) -> 0 | M14: =L14*35% -> 0 | O14: =N14*35% -> 0 | Q14: =P14*30% -> 0 | R14: =ROUND((M14+O14+Q14),2) -> 0 | T14: =S14*35% -> 0 | V14: =U14*35% -> 0 | X14: =W14*30% -> 0 | Y14: =ROUND((T14+V14+X14),2) -> 0 | AA14: =Z14*35% -> 0 | AC14: =AB14*35% -> 0 | AE14: =AD14*30% -> 0 | AF14: =ROUND((AA14+AC14+AE14),2) -> 0 | AG14: =VALUE((K14+R14+Y14+AF14)/4) -> 0 | AH14: =ROUND(AG14,1) -> 0 | AJ14: =IF(AI14<=0,AH14,(AH14+AI14)/2) -> 0
A15: 6 | D15: F | F15: =E15*35% -> 0 | H15: =G15*35% -> 0 | J15: =I15*30% -> 0 | K15: =ROUND((F15+H15+J15),2) -> 0 | M15: =L15*35% -> 0 | O15: =N15*35% -> 0 | Q15: =P15*30% -> 0 | R15: =ROUND((M15+O15+Q15),2) -> 0 | T15: =S15*35% -> 0 | V15: =U15*35% -> 0 | X15: =W15*30% -> 0 | Y15: =ROUND((T15+V15+X15),2) -> 0 | AA15: =Z15*35% -> 0 | AC15: =AB15*35% -> 0 | AE15: =AD15*30% -> 0 | AF15: =ROUND((AA15+AC15+AE15),2) -> 0 | AG15: =VALUE((K15+R15+Y15+AF15)/4) -> 0 | AH15: =ROUND(AG15,1) -> 0 | AJ15: =IF(AI15<=0,AH15,(AH15+AI15)/2) -> 0
A16: 7 | D16: M | F16: =E16*35% -> 0 | H16: =G16*35% -> 0 | J16: =I16*30% -> 0 | K16: =ROUND((F16+H16+J16),2) -> 0 | M16: =L16*35% -> 0 | O16: =N16*35% -> 0 | Q16: =P16*30% -> 0 | R16: =ROUND((M16+O16+Q16),2) -> 0 | T16: =S16*35% -> 0 | V16: =U16*35% -> 0 | X16: =W16*30% -> 0 | Y16: =ROUND((T16+V16+X16),2) -> 0 | AA16: =Z16*35% -> 0 | AC16: =AB16*35% -> 0 | AE16: =AD16*30% -> 0 | AF16: =ROUND((AA16+AC16+AE16),2) -> 0 | AG16: =VALUE((K16+R16+Y16+AF16)/4) -> 0 | AH16: =ROUND(AG16,1) -> 0 | AJ16: =IF(AI16<=0,AH16,(AH16+AI16)/2) -> 0
A17: 8 | D17: M | F17: =E17*35% -> 0 | H17: =G17*35% -> 0 | J17: =I17*30% -> 0 | K17: =ROUND((F17+H17+J17),2) -> 0 | M17: =L17*35% -> 0 | O17: =N17*35% -> 0 | Q17: =P17*30% -> 0 | R17: =ROUND((M17+O17+Q17),2) -> 0 | T17: =S17*35% -> 0 | V17: =U17*35% -> 0 | X17: =W17*30% -> 0 | Y17: =ROUND((T17+V17+X17),2) -> 0 | AA17: =Z17*35% -> 0 | AC17: =AB17*35% -> 0 | AE17: =AD17*30% -> 0 | AF17: =ROUND((AA17+AC17+AE17),2) -> 0 | AG17: =VALUE((K17+R17+Y17+AF17)/4) -> 0 | AH17: =ROUND(AG17,1) -> 0 | AJ17: =IF(AI17<=0,AH17,(AH17+AI17)/2) -> 0
A18: 9 | D18: M | F18: =E18*35% -> 0 | H18: =G18*35% -> 0 | J18: =I18*30% -> 0 | K18: =ROUND((F18+H18+J18),2) -> 0 | M18: =L18*35% -> 0 | O18: =N18*35% -> 0 | Q18: =P18*30% -> 0 | R18: =ROUND((M18+O18+Q18),2) -> 0 | T18: =S18*35% -> 0 | V18: =U18*35% -> 0 | X18: =W18*30% -> 0 | Y18: =ROUND((T18+V18+X18),2) -> 0 | AA18: =Z18*35% -> 0 | AC18: =AB18*35% -> 0 | AE18: =AD18*30% -> 0 | AF18: =ROUND((AA18+AC18+AE18),2) -> 0 | AG18: =VALUE((K18+R18+Y18+AF18)/4) -> 0 | AH18: =ROUND(AG18,1) -> 0 | AJ18: =IF(AI18<=0,AH18,(AH18+AI18)/2) -> 0
A19: 10 | D19: F | F19: =E19*35% -> 0 | H19: =G19*35% -> 0 | J19: =I19*30% -> 0 | K19: =ROUND((F19+H19+J19),2) -> 0 | M19: =L19*35% -> 0 | O19: =N19*35% -> 0 | Q19: =P19*30% -> 0 | R19: =ROUND((M19+O19+Q19),2) -> 0 | T19: =S19*35% -> 0 | V19: =U19*35% -> 0 | X19: =W19*30% -> 0 | Y19: =ROUND((T19+V19+X19),2) -> 0 | AA19: =Z19*35% -> 0 | AC19: =AB19*35% -> 0 | AE19: =AD19*30% -> 0 | AF19: =ROUND((AA19+AC19+AE19),2) -> 0 | AG19: =VALUE((K19+R19+Y19+AF19)/4) -> 0 | AH19: =ROUND(AG19,1) -> 0 | AJ19: =IF(AI19<=0,AH19,(AH19+AI19)/2) -> 0
A20: 11 | D20: M | F20: =E20*35% -> 0 | H20: =G20*35% -> 0 | J20: =I20*30% -> 0 | K20: =ROUND((F20+H20+J20),2) -> 0 | M20: =L20*35% -> 0 | O20: =N20*35% -> 0 | Q20: =P20*30% -> 0 | R20: =ROUND((M20+O20+Q20),2) -> 0 | T20: =S20*35% -> 0 | V20: =U20*35% -> 0 | X20: =W20*30% -> 0 | Y20: =ROUND((T20+V20+X20),2) -> 0 | AA20: =Z20*35% -> 0 | AC20: =AB20*35% -> 0 | AE20: =AD20*30% -> 0 | AF20: =ROUND((AA20+AC20+AE20),2) -> 0 | AG20: =VALUE((K20+R20+Y20+AF20)/4) -> 0 | AH20: =ROUND(AG20,1) -> 0 | AJ20: =IF(AI20<=0,AH20,(AH20+AI20)/2) -> 0
A21: 12 | D21: M | F21: =E21*35% -> 0 | H21: =G21*35% -> 0 | J21: =I21*30% -> 0 | K21: =ROUND((F21+H21+J21),2) -> 0 | M21: =L21*35% -> 0 | O21: =N21*35% -> 0 | Q21: =P21*30% -> 0 | R21: =ROUND((M21+O21+Q21),2) -> 0 | T21: =S21*35% -> 0 | V21: =U21*35% -> 0 | X21: =W21*30% -> 0 | Y21: =ROUND((T21+V21+X21),2) -> 0 | AA21: =Z21*35% -> 0 | AC21: =AB21*35% -> 0 | AE21: =AD21*30% -> 0 | AF21: =ROUND((AA21+AC21+AE21),2) -> 0 | AG21: =VALUE((K21+R21+Y21+AF21)/4) -> 0 | AH21: =ROUND(AG21,1) -> 0 | AJ21: =IF(AI21<=0,AH21,(AH21+AI21)/2) -> 0
... A33: 25 | D33: M | F33: =E33*35% -> 0 | H33: =G33*35% -> 0 | J33: =I33*30% -> 0 | K33: =ROUND((F33+H33+J33),2) -> 0 | M33: =L33*35% -> 0 | O33: =N33*35% -> 0 | Q33: =P33*30% -> 0 | R33: =ROUND((M33+O33+Q33),2) -> 0 | T33: =S33*35% -> 0 | V33: =U33*35% -> 0 | X33: =W33*30% -> 0 | Y33: =ROUND((T33+V33+X33),2) -> 0 | AA33: =Z33*35% -> 0 | AC33: =AB33*35% -> 0 | AE33: =AD33*30% -> 0 | AF33: =ROUND((AA33+AC33+AE33),2) -> 0 | AG33: =VALUE((K33+R33+Y33+AF33)/4) -> 0 | AH33: =ROUND(AG33,1) -> 0 | AJ33: =IF(AI33<=0,AH33,(AH33+AI33)/2) -> 0
A34: 26 | D34: M | F34: =E34*35% -> 0 | H34: =G34*35% -> 0 | J34: =I34*30% -> 0 | K34: =ROUND((F34+H34+J34),2) -> 0 | M34: =L34*35% -> 0 | O34: =N34*35% -> 0 | Q34: =P34*30% -> 0 | R34: =ROUND((M34+O34+Q34),2) -> 0 | T34: =S34*35% -> 0 | V34: =U34*35% -> 0 | X34: =W34*30% -> 0 | Y34: =ROUND((T34+V34+X34),2) -> 0 | AA34: =Z34*35% -> 0 | AC34: =AB34*35% -> 0 | AE34: =AD34*30% -> 0 | AF34: =ROUND((AA34+AC34+AE34),2) -> 0 | AG34: =VALUE((K34+R34+Y34+AF34)/4) -> 0 | AH34: =ROUND(AG34,1) -> 0 | AJ34: =IF(AI34<=0,AH34,(AH34+AI34)/2) -> 0 | AL34: Escala de Calificación
A35: 27 | D35: F | F35: =E35*35% -> 0 | H35: =G35*35% -> 0 | J35: =I35*30% -> 0 | K35: =ROUND((F35+H35+J35),2) -> 0 | M35: =L35*35% -> 0 | O35: =N35*35% -> 0 | Q35: =P35*30% -> 0 | R35: =ROUND((M35+O35+Q35),2) -> 0 | T35: =S35*35% -> 0 | V35: =U35*35% -> 0 | X35: =W35*30% -> 0 | Y35: =ROUND((T35+V35+X35),2) -> 0 | AA35: =Z35*35% -> 0 | AC35: =AB35*35% -> 0 | AE35: =AD35*30% -> 0 | AF35: =ROUND((AA35+AC35+AE35),2) -> 0 | AG35: =VALUE((K35+R35+Y35+AF35)/4) -> 0 | AH35: =ROUND(AG35,1) -> 0 | AJ35: =IF(AI35<=0,AH35,(AH35+AI35)/2) -> 0 | AL35: 9-10= Excelente
A36: 28 | D36: M | F36: =E36*35% -> 0 | H36: =G36*35% -> 0 | J36: =I36*30% -> 0 | K36: =ROUND((F36+H36+J36),2) -> 0 | M36: =L36*35% -> 0 | O36: =N36*35% -> 0 | Q36: =P36*30% -> 0 | R36: =ROUND((M36+O36+Q36),2) -> 0 | T36: =S36*35% -> 0 | V36: =U36*35% -> 0 | X36: =W36*30% -> 0 | Y36: =ROUND((T36+V36+X36),2) -> 0 | AA36: =Z36*35% -> 0 | AC36: =AB36*35% -> 0 | AE36: =AD36*30% -> 0 | AF36: =ROUND((AA36+AC36+AE36),2) -> 0 | AG36: =VALUE((K36+R36+Y36+AF36)/4) -> 0 | AH36: =ROUND(AG36,1) -> 0 | AJ36: =IF(AI36<=0,AH36,(AH36+AI36)/2) -> 0 | AL36: 7- 8= Muy Bueno
A37: 29 | F37: =E37*35% -> 0 | H37: =G37*35% -> 0 | J37: =I37*30% -> 0 | K37: =ROUND((F37+H37+J37),2) -> 0 | M37: =L37*35% -> 0 | O37: =N37*35% -> 0 | Q37: =P37*30% -> 0 | R37: =ROUND((M37+O37+Q37),2) -> 0 | T37: =S37*35% -> 0 | V37: =U37*35% -> 0 | X37: =W37*30% -> 0 | Y37: =ROUND((T37+V37+X37),2) -> 0 | AA37: =Z37*35% -> 0 | AC37: =AB37*35% -> 0 | AE37: =AD37*30% -> 0 | AF37: =ROUND((AA37+AC37+AE37),2) -> 0 | AG37: =VALUE((K37+R37+Y37+AF37)/4) -> 0 | AH37: =ROUND(AG37,1) -> 0 | AJ37: =IF(AI37<=0,AH37,(AH37+AI37)/2) -> 0 | AL37: 5- 6= Bueno
A38: 30 | F38: =E38*35% -> 0 | H38: =G38*35% -> 0 | J38: =I38*30% -> 0 | K38: =ROUND((F38+H38+J38),2) -> 0 | M38: =L38*35% -> 0 | O38: =N38*35% -> 0 | Q38: =P38*30% -> 0 | R38: =ROUND((M38+O38+Q38),2) -> 0 | T38: =S38*35% -> 0 | V38: =U38*35% -> 0 | X38: =W38*30% -> 0 | Y38: =ROUND((T38+V38+X38),2) -> 0 | AA38: =Z38*35% -> 0 | AC38: =AB38*35% -> 0 | AE38: =AD38*30% -> 0 | AF38: =ROUND((AA38+AC38+AE38),2) -> 0 | AG38: =VALUE((K38+R38+Y38+AF38)/4) -> 0 | AH38: =ROUND(AG38,1) -> 0 | AJ38: =IF(AI38<=0,AH38,(AH38+AI38)/2) -> 0 | AL38: 3- 4= Regular
A39: 31 | F39: =E39*35% -> 0 | H39: =G39*35% -> 0 | J39: =I39*30% -> 0 | K39: =ROUND((F39+H39+J39),2) -> 0 | M39: =L39*35% -> 0 | O39: =N39*35% -> 0 | Q39: =P39*30% -> 0 | R39: =ROUND((M39+O39+Q39),2) -> 0 | T39: =S39*35% -> 0 | V39: =U39*35% -> 0 | X39: =W39*30% -> 0 | Y39: =ROUND((T39+V39+X39),2) -> 0 | AA39: =Z39*35% -> 0 | AC39: =AB39*35% -> 0 | AE39: =AD39*30% -> 0 | AF39: =ROUND((AA39+AC39+AE39),2) -> 0 | AG39: =VALUE((K39+R39+Y39+AF39)/4) -> 0 | AH39: =ROUND(AG39,1) -> 0 | AJ39: =IF(AI39<=0,AH39,(AH39+AI39)/2) -> 0 | AL39: 1- 2= Necesita Mejorar
A40: 32 | F40: =E40*35% -> 0 | H40: =G40*35% -> 0 | J40: =I40*30% -> 0 | K40: =ROUND((F40+H40+J40),2) -> 0 | M40: =L40*35% -> 0 | O40: =N40*35% -> 0 | Q40: =P40*30% -> 0 | R40: =ROUND((M40+O40+Q40),2) -> 0 | T40: =S40*35% -> 0 | V40: =U40*35% -> 0 | X40: =W40*30% -> 0 | Y40: =ROUND((T40+V40+X40),2) -> 0 | AA40: =Z40*35% -> 0 | AC40: =AB40*35% -> 0 | AE40: =AD40*30% -> 0 | AF40: =ROUND((AA40+AC40+AE40),2) -> 0 | AG40: =VALUE((K40+R40+Y40+AF40)/4) -> 0 | AH40: =ROUND(AG40,1) -> 0 | AJ40: =IF(AI40<=0,AH40,(AH40+AI40)/2) -> 0
A41: 33 | F41: =E41*35% -> 0 | H41: =G41*35% -> 0 | J41: =I41*30% -> 0 | K41: =ROUND((F41+H41+J41),2) -> 0 | M41: =L41*35% -> 0 | O41: =N41*35% -> 0 | Q41: =P41*30% -> 0 | R41: =ROUND((M41+O41+Q41),2) -> 0 | T41: =S41*35% -> 0 | V41: =U41*35% -> 0 | X41: =W41*30% -> 0 | Y41: =ROUND((T41+V41+X41),2) -> 0 | AA41: =Z41*35% -> 0 | AC41: =AB41*35% -> 0 | AE41: =AD41*30% -> 0 | AF41: =ROUND((AA41+AC41+AE41),2) -> 0 | AG41: =VALUE((K41+R41+Y41+AF41)/4) -> 0 | AH41: =ROUND(AG41,1) -> 0 | AJ41: =IF(AI41<=0,AH41,(AH41+AI41)/2) -> 0
A42: 34 | F42: =E42*35% -> 0 | H42: =G42*35% -> 0 | J42: =I42*30% -> 0 | K42: =ROUND((F42+H42+J42),2) -> 0 | M42: =L42*35% -> 0 | O42: =N42*35% -> 0 | Q42: =P42*30% -> 0 | R42: =ROUND((M42+O42+Q42),2) -> 0 | T42: =S42*35% -> 0 | V42: =U42*35% -> 0 | X42: =W42*30% -> 0 | Y42: =ROUND((T42+V42+X42),2) -> 0 | AA42: =Z42*35% -> 0 | AC42: =AB42*35% -> 0 | AE42: =AD42*30% -> 0 | AF42: =ROUND((AA42+AC42+AE42),2) -> 0 | AG42: =VALUE((K42+R42+Y42+AF42)/4) -> 0 | AH42: =ROUND(AG42,1) -> 0 | AJ42: =IF(AI42<=0,AH42,(AH42+AI42)/2) -> 0 | AL42: =AJ5 -> Grado
A43: 35 | F43: =E43*35% -> 0 | H43: =G43*35% -> 0 | J43: =I43*30% -> 0 | K43: =ROUND((F43+H43+J43),2) -> 0 | M43: =L43*35% -> 0 | O43: =N43*35% -> 0 | Q43: =P43*30% -> 0 | R43: =ROUND((M43+O43+Q43),2) -> 0 | T43: =S43*35% -> 0 | V43: =U43*35% -> 0 | X43: =W43*30% -> 0 | Y43: =ROUND((T43+V43+X43),2) -> 0 | AA43: =Z43*35% -> 0 | AC43: =AB43*35% -> 0 | AE43: =AD43*30% -> 0 | AF43: =ROUND((AA43+AC43+AE43),2) -> 0 | AG43: =VALUE((K43+R43+Y43+AF43)/4) -> 0 | AH43: =ROUND(AG43,1) -> 0 | AJ43: =IF(AI43<=0,AH43,(AH43+AI43)/2) -> 0 | AL43: =A4 -> 0
A44: 36 | F44: =E44*35% -> 0 | H44: =G44*35% -> 0 | J44: =I44*30% -> 0 | K44: =ROUND((F44+H44+J44),2) -> 0 | M44: =L44*35% -> 0 | O44: =N44*35% -> 0 | Q44: =P44*30% -> 0 | R44: =ROUND((M44+O44+Q44),2) -> 0 | T44: =S44*35% -> 0 | V44: =U44*35% -> 0 | X44: =W44*30% -> 0 | Y44: =ROUND((T44+V44+X44),2) -> 0 | AA44: =Z44*35% -> 0 | AC44: =AB44*35% -> 0 | AE44: =AD44*30% -> 0 | AF44: =ROUND((AA44+AC44+AE44),2) -> 0 | AG44: =VALUE((K44+R44+Y44+AF44)/4) -> 0 | AH44: =ROUND(AG44,1) -> 0 | AJ44: =IF(AI44<=0,AH44,(AH44+AI44)/2) -> 0 | AL44: =H5 -> " B "
A45: 37 | F45: =E45*35% -> 0 | H45: =G45*35% -> 0 | J45: =I45*30% -> 0 | K45: =ROUND((F45+H45+J45),2) -> 0 | M45: =L45*35% -> 0 | O45: =N45*35% -> 0 | Q45: =P45*30% -> 0 | R45: =ROUND((M45+O45+Q45),2) -> 0 | T45: =S45*35% -> 0 | V45: =U45*35% -> 0 | X45: =W45*30% -> 0 | Y45: =ROUND((T45+V45+X45),2) -> 0 | AA45: =Z45*35% -> 0 | AC45: =AB45*35% -> 0 | AE45: =AD45*30% -> 0 | AF45: =ROUND((AA45+AC45+AE45),2) -> 0 | AG45: =VALUE((K45+R45+Y45+AF45)/4) -> 0 | AH45: =ROUND(AG45,1) -> 0 | AJ45: =IF(AI45<=0,AH45,(AH45+AI45)/2) -> 0
A46: 38 | F46: =E46*35% -> 0 | H46: =G46*35% -> 0 | J46: =I46*30% -> 0 | K46: =ROUND((F46+H46+J46),2) -> 0 | M46: =L46*35% -> 0 | O46: =N46*35% -> 0 | Q46: =P46*30% -> 0 | R46: =ROUND((M46+O46+Q46),2) -> 0 | T46: =S46*35% -> 0 | V46: =U46*35% -> 0 | X46: =W46*30% -> 0 | Y46: =ROUND((T46+V46+X46),2) -> 0 | AA46: =Z46*35% -> 0 | AC46: =AB46*35% -> 0 | AE46: =AD46*30% -> 0 | AF46: =ROUND((AA46+AC46+AE46),2) -> 0 | AG46: =VALUE((K46+R46+Y46+AF46)/4) -> 0 | AH46: =ROUND(AG46,1) -> 0 | AJ46: =IF(AI46<=0,AH46,(AH46+AI46)/2) -> 0 | AL46: =D1 -> AÑO: 2026
A47: 39 | F47: =E47*35% -> 0 | H47: =G47*35% -> 0 | J47: =I47*30% -> 0 | K47: =ROUND((F47+H47+J47),2) -> 0 | M47: =L47*35% -> 0 | O47: =N47*35% -> 0 | Q47: =P47*30% -> 0 | R47: =ROUND((M47+O47+Q47),2) -> 0 | T47: =S47*35% -> 0 | V47: =U47*35% -> 0 | X47: =W47*30% -> 0 | Y47: =ROUND((T47+V47+X47),2) -> 0 | AA47: =Z47*35% -> 0 | AC47: =AB47*35% -> 0 | AE47: =AD47*30% -> 0 | AF47: =ROUND((AA47+AC47+AE47),2) -> 0 | AG47: =VALUE((K47+R47+Y47+AF47)/4) -> 0 | AH47: =ROUND(AG47,1) -> 0 | AJ47: =IF(AI47<=0,AH47,(AH47+AI47)/2) -> 0
A48: 40 | F48: =E48*35% -> 0 | H48: =G48*35% -> 0 | J48: =I48*30% -> 0 | K48: =ROUND((F48+H48+J48),2) -> 0 | M48: =L48*35% -> 0 | O48: =N48*35% -> 0 | Q48: =P48*30% -> 0 | R48: =ROUND((M48+O48+Q48),2) -> 0 | T48: =S48*35% -> 0 | V48: =U48*35% -> 0 | X48: =W48*30% -> 0 | Y48: =ROUND((T48+V48+X48),2) -> 0 | AA48: =Z48*35% -> 0 | AC48: =AB48*35% -> 0 | AE48: =AD48*30% -> 0 | AF48: =ROUND((AA48+AC48+AE48),2) -> 0 | AG48: =VALUE((K48+R48+Y48+AF48)/4) -> 0 | AH48: =ROUND(AG48,1) -> 0 | AJ48: =IF(AH48>=5.5,AH48,(AH48+AI48)/2) -> 0 | AL48: =AA5 -> LIDIA CONCEPCION GONZALEZ DE CABALLERO
A49: 41 | F49: =E49*35% -> 0 | H49: =G49*35% -> 0 | J49: =I49*30% -> 0 | K49: =ROUND((F49+H49+J49),2) -> 0 | M49: =L49*35% -> 0 | O49: =N49*35% -> 0 | Q49: =P49*30% -> 0 | R49: =ROUND((M49+O49+Q49),2) -> 0 | T49: =S49*35% -> 0 | V49: =U49*35% -> 0 | X49: =W49*30% -> 0 | Y49: =ROUND((T49+V49+X49),2) -> 0 | AA49: =Z49*35% -> 0 | AC49: =AB49*35% -> 0 | AE49: =AD49*30% -> 0 | AF49: =ROUND((AA49+AC49+AE49),2) -> 0 | AG49: =VALUE((K49+R49+Y49+AF49)/4) -> 0 | AH49: =ROUND(AG49,1) -> 0 | AJ49: =IF(AH49>=5.5,AH49,(AH49+AI49)/2) -> 0
A50: 42 | F50: =E50*35% -> 0 | H50: =G50*35% -> 0 | J50: =I50*30% -> 0 | K50: =ROUND((F50+H50+J50),2) -> 0 | M50: =L50*35% -> 0 | O50: =N50*35% -> 0 | Q50: =P50*30% -> 0 | R50: =ROUND((M50+O50+Q50),2) -> 0 | T50: =S50*35% -> 0 | V50: =U50*35% -> 0 | X50: =W50*30% -> 0 | Y50: =ROUND((T50+V50+X50),2) -> 0 | AA50: =Z50*35% -> 0 | AC50: =AB50*35% -> 0 | AE50: =AD50*30% -> 0 | AF50: =ROUND((AA50+AC50+AE50),2) -> 0 | AG50: =VALUE((K50+R50+Y50+AF50)/4) -> 0 | AH50: =ROUND(AG50,1) -> 0 | AJ50: =IF(AH50>=5.5,AH50,(AH50+AI50)/2) -> 0
A51: 43 | F51: =E51*35% -> 0 | H51: =G51*35% -> 0 | J51: =I51*30% -> 0 | K51: =ROUND((F51+H51+J51),2) -> 0 | M51: =L51*35% -> 0 | O51: =N51*35% -> 0 | Q51: =P51*30% -> 0 | R51: =ROUND((M51+O51+Q51),2) -> 0 | T51: =S51*35% -> 0 | V51: =U51*35% -> 0 | X51: =W51*30% -> 0 | Y51: =ROUND((T51+V51+X51),2) -> 0 | AA51: =Z51*35% -> 0 | AC51: =AB51*35% -> 0 | AE51: =AD51*30% -> 0 | AF51: =ROUND((AA51+AC51+AE51),2) -> 0 | AG51: =VALUE((K51+R51+Y51+AF51)/4) -> 0 | AH51: =ROUND(AG51,1) -> 0 | AJ51: =IF(AH51>=5.5,AH51,(AH51+AI51)/2) -> 0
...

Sheet Hoja1
A1: # | B1: ASIG | C1: eval | D1: nie | E1: nota | F1: nota2 | G1: nota3 | H1: nota4
A2: 1 | D2: ='PLANILLA PARA MATERIA'!B10 -> 0 | E2: ='PLANILLA PARA MATERIA'!K10 -> 0 | F2: ='PLANILLA PARA MATERIA'!R10 -> 0 | G2: ='PLANILLA PARA MATERIA'!Y10 -> 0 | H2: ='PLANILLA PARA MATERIA'!AF10 -> 0
A3: 2 | D3: ='PLANILLA PARA MATERIA'!B11 -> 0 | E3: ='PLANILLA PARA MATERIA'!K11 -> 0 | F3: ='PLANILLA PARA MATERIA'!R11 -> 0 | G3: ='PLANILLA PARA MATERIA'!Y11 -> 0 | H3: ='PLANILLA PARA MATERIA'!AF11 -> 0
A4: 3 | D4: ='PLANILLA PARA MATERIA'!B12 -> 0 | E4: ='PLANILLA PARA MATERIA'!K12 -> 0 | F4: ='PLANILLA PARA MATERIA'!R12 -> 0 | G4: ='PLANILLA PARA MATERIA'!Y12 -> 0 | H4: ='PLANILLA PARA MATERIA'!AF12 -> 0
A5: 4 | D5: ='PLANILLA PARA MATERIA'!B13 -> 0 | E5: ='PLANILLA PARA MATERIA'!K13 -> 0 | F5: ='PLANILLA PARA MATERIA'!R13 -> 0 | G5: ='PLANILLA PARA MATERIA'!Y13 -> 0 | H5: ='PLANILLA PARA MATERIA'!AF13 -> 0
A6: 5 | D6: ='PLANILLA PARA MATERIA'!B14 -> 0 | E6: ='PLANILLA PARA MATERIA'!K14 -> 0 | F6: ='PLANILLA PARA MATERIA'!R14 -> 0 | G6: ='PLANILLA PARA MATERIA'!Y14 -> 0 | H6: ='PLANILLA PARA MATERIA'!AF14 -> 0
A7: 6 | D7: ='PLANILLA PARA MATERIA'!B15 -> 0 | E7: ='PLANILLA PARA MATERIA'!K15 -> 0 | F7: ='PLANILLA PARA MATERIA'!R15 -> 0 | G7: ='PLANILLA PARA MATERIA'!Y15 -> 0 | H7: ='PLANILLA PARA MATERIA'!AF15 -> 0
A8: 7 | D8: ='PLANILLA PARA MATERIA'!B16 -> 0 | E8: ='PLANILLA PARA MATERIA'!K16 -> 0 | F8: ='PLANILLA PARA MATERIA'!R16 -> 0 | G8: ='PLANILLA PARA MATERIA'!Y16 -> 0 | H8: ='PLANILLA PARA MATERIA'!AF16 -> 0
A9: 8 | D9: ='PLANILLA PARA MATERIA'!B17 -> 0 | E9: ='PLANILLA PARA MATERIA'!K17 -> 0 | F9: ='PLANILLA PARA MATERIA'!R17 -> 0 | G9: ='PLANILLA PARA MATERIA'!Y17 -> 0 | H9: ='PLANILLA PARA MATERIA'!AF17 -> 0
A10: 9 | D10: ='PLANILLA PARA MATERIA'!B18 -> 0 | E10: ='PLANILLA PARA MATERIA'!K18 -> 0 | F10: ='PLANILLA PARA MATERIA'!R18 -> 0 | G10: ='PLANILLA PARA MATERIA'!Y18 -> 0 | H10: ='PLANILLA PARA MATERIA'!AF18 -> 0
A11: 10 | D11: ='PLANILLA PARA MATERIA'!B19 -> 0 | E11: ='PLANILLA PARA MATERIA'!K19 -> 0 | F11: ='PLANILLA PARA MATERIA'!R19 -> 0 | G11: ='PLANILLA PARA MATERIA'!Y19 -> 0 | H11: ='PLANILLA PARA MATERIA'!AF19 -> 0
A12: 11 | D12: ='PLANILLA PARA MATERIA'!B20 -> 0 | E12: ='PLANILLA PARA MATERIA'!K20 -> 0 | F12: ='PLANILLA PARA MATERIA'!R20 -> 0 | G12: ='PLANILLA PARA MATERIA'!Y20 -> 0 | H12: ='PLANILLA PARA MATERIA'!AF20 -> 0
A13: 12 | D13: ='PLANILLA PARA MATERIA'!B21 -> 0 | E13: ='PLANILLA PARA MATERIA'!K21 -> 0 | F13: ='PLANILLA PARA MATERIA'!R21 -> 0 | G13: ='PLANILLA PARA MATERIA'!Y21 -> 0 | H13: ='PLANILLA PARA MATERIA'!AF21 -> 0
... A22: 21 | D22: ='PLANILLA PARA MATERIA'!B30 -> 0 | E22: ='PLANILLA PARA MATERIA'!K30 -> 0 | F22: ='PLANILLA PARA MATERIA'!R30 -> 0 | G22: ='PLANILLA PARA MATERIA'!Y30 -> 0 | H22: ='PLANILLA PARA MATERIA'!AF30 -> 0
A23: 22 | D23: =#REF! -> #REF! | E23: =#REF! -> #REF! | F23: =#REF! -> #REF! | G23: =#REF! -> #REF! | H23: =#REF! -> #REF!
A24: 23 | D24: ='PLANILLA PARA MATERIA'!B31 -> 0 | E24: ='PLANILLA PARA MATERIA'!K31 -> 0 | F24: ='PLANILLA PARA MATERIA'!R31 -> 0 | G24: ='PLANILLA PARA MATERIA'!Y31 -> 0 | H24: ='PLANILLA PARA MATERIA'!AF31 -> 0
A25: 24 | D25: ='PLANILLA PARA MATERIA'!B32 -> 0 | E25: ='PLANILLA PARA MATERIA'!K32 -> 0 | F25: ='PLANILLA PARA MATERIA'!R32 -> 0 | G25: ='PLANILLA PARA MATERIA'!Y32 -> 0 | H25: ='PLANILLA PARA MATERIA'!AF32 -> 0
A26: 25 | D26: ='PLANILLA PARA MATERIA'!B33 -> 0 | E26: ='PLANILLA PARA MATERIA'!K33 -> 0 | F26: ='PLANILLA PARA MATERIA'!R33 -> 0 | G26: ='PLANILLA PARA MATERIA'!Y33 -> 0 | H26: ='PLANILLA PARA MATERIA'!AF33 -> 0
A27: 26 | D27: ='PLANILLA PARA MATERIA'!B34 -> 0 | E27: ='PLANILLA PARA MATERIA'!K34 -> 0 | F27: ='PLANILLA PARA MATERIA'!R34 -> 0 | G27: ='PLANILLA PARA MATERIA'!Y34 -> 0 | H27: ='PLANILLA PARA MATERIA'!AF34 -> 0
A28: 27 | D28: ='PLANILLA PARA MATERIA'!B35 -> 0 | E28: ='PLANILLA PARA MATERIA'!K35 -> 0 | F28: ='PLANILLA PARA MATERIA'!R35 -> 0 | G28: ='PLANILLA PARA MATERIA'!Y35 -> 0 | H28: ='PLANILLA PARA MATERIA'!AF35 -> 0
A29: 28 | D29: ='PLANILLA PARA MATERIA'!B36 -> 0 | E29: ='PLANILLA PARA MATERIA'!K36 -> 0 | F29: ='PLANILLA PARA MATERIA'!R36 -> 0 | G29: ='PLANILLA PARA MATERIA'!Y36 -> 0 | H29: ='PLANILLA PARA MATERIA'!AF36 -> 0
A30: 29 | D30: ='PLANILLA PARA MATERIA'!B37 -> 0 | E30: ='PLANILLA PARA MATERIA'!K37 -> 0 | F30: ='PLANILLA PARA MATERIA'!R37 -> 0 | G30: ='PLANILLA PARA MATERIA'!Y37 -> 0 | H30: ='PLANILLA PARA MATERIA'!AF37 -> 0
A31: 30 | D31: ='PLANILLA PARA MATERIA'!B38 -> 0 | E31: ='PLANILLA PARA MATERIA'!K38 -> 0 | F31: ='PLANILLA PARA MATERIA'!R38 -> 0 | G31: ='PLANILLA PARA MATERIA'!Y38 -> 0 | H31: ='PLANILLA PARA MATERIA'!AF38 -> 0
A32: 31 | D32: ='PLANILLA PARA MATERIA'!B39 -> 0 | E32: ='PLANILLA PARA MATERIA'!K39 -> 0 | F32: ='PLANILLA PARA MATERIA'!R39 -> 0 | G32: ='PLANILLA PARA MATERIA'!Y39 -> 0 | H32: ='PLANILLA PARA MATERIA'!AF39 -> 0
A33: 32 | D33: ='PLANILLA PARA MATERIA'!B40 -> 0 | E33: ='PLANILLA PARA MATERIA'!K40 -> 0 | F33: ='PLANILLA PARA MATERIA'!R40 -> 0 | G33: ='PLANILLA PARA MATERIA'!Y40 -> 0 | H33: ='PLANILLA PARA MATERIA'!AF40 -> 0
A34: 33 | D34: ='PLANILLA PARA MATERIA'!B41 -> 0 | E34: ='PLANILLA PARA MATERIA'!K41 -> 0 | F34: ='PLANILLA PARA MATERIA'!R41 -> 0 | G34: ='PLANILLA PARA MATERIA'!Y41 -> 0 | H34: ='PLANILLA PARA MATERIA'!AF41 -> 0
A35: 34 | D35: ='PLANILLA PARA MATERIA'!B42 -> 0 | E35: ='PLANILLA PARA MATERIA'!K42 -> 0 | F35: ='PLANILLA PARA MATERIA'!R42 -> 0 | G35: ='PLANILLA PARA MATERIA'!Y42 -> 0 | H35: ='PLANILLA PARA MATERIA'!AF42 -> 0
... A56: 55 | D56: ='PLANILLA PARA MATERIA'!B63 -> 0 | E56: ='PLANILLA PARA MATERIA'!K63 -> 0 | F56: ='PLANILLA PARA MATERIA'!R63 -> 0 | G56: ='PLANILLA PARA MATERIA'!Y63 -> 0 | H56: ='PLANILLA PARA MATERIA'!AF63 -> 0

Sheet plantilla para módulos
A1: INSTITUTO NACIONAL DE SANTIAGO DE MARÍA
A2: CUADRO DE EVALUACIÓN POR MÓDULO
A3: MUNICIPIO: SANTIAGO DE MARÍA | F3: DEPARTAMENTO: USULUTÁN | M3: AÑO: | N3: 2026
A4: BACHILLERATO TECNICO: | L4: SECCIÓN: | N4: "__"
A5: NOMBRE DEL MÓDULO: | D5: ____________________________________________________________________________________________________________
A6: NOMBRE DEL DOCENTE: | N6: AÑO DEL BACHILLERATO:
A7: N° | B7: NIE | C7: NOMBRE DEL ALUMNO/A | D7: GENERO | E7: PREPARACIÓN | J7: EJECUCIÓN | O7: EVALUACIÓN | T7: PROMEDIO | V7: PROMEDIO FINAL
E8: EVALUACIÓN | F8: AUTOEVALUACIÓN | G8: HETEROEVALUACIÓN | H8: PROMEDIO | I8: 0.25 | J8: EVALUACIÓN | K8: AUTOEVALUACIÓN | L8: HETEROEVALUACIÓN | M8: PROMEDIO | N8: 0.5 | O8: EVALUACIÓN | P8: AUTOEVALUACIÓN | Q8: HETEROEVALUACIÓN | R8: PROMEDIO | S8: 0.25 | T8: ORDINARIO | U8: RECUPERACIÓN
A9: 1 | B9: 19770108 | C9: AMAYA CASTRO, JIMENA GRISBEL | D9: F | H9: =(E9+F9+G9)/3 -> 0 | I9: =H9*0.125 -> 0 | M9: =(J9+K9+L9)/3 -> 0 | N9: =M9*0.25 -> 0 | R9: =(O9+P9+Q9)/3 -> 0 | S9: =R9*0.125 -> 0 | T9: =(I9+N9+S9) -> 0 | V9: =IF(U9<=0,T9,(T9+U9)/2) -> 0
A10: 2 | B10: 3669191 | C10: ARAUJO ROJAS, RICARDO ALEXANDER | D10: M | H10: =(E10+F10+G10)/3 -> 0 | I10: =H10*0.125 -> 0 | M10: =(J10+K10+L10)/3 -> 0 | N10: =M10*0.25 -> 0 | R10: =(O10+P10+Q10)/3 -> 0 | S10: =R10*0.125 -> 0 | T10: =(I10+N10+S10) -> 0 | V10: =IF(U10<=0,T10,(T10+U10)/2) -> 0
A11: 3 | B11: 19913116 | C11: AYALA DÍAZ, WALTER EMMANUEL | D11: M | H11: =(E11+F11+G11)/3 -> 0 | I11: =H11*0.125 -> 0 | M11: =(J11+K11+L11)/3 -> 0 | N11: =M11*0.25 -> 0 | R11: =(O11+P11+Q11)/3 -> 0 | S11: =R11*0.125 -> 0 | T11: =(I11+N11+S11) -> 0 | V11: =IF(U11<=0,T11,(T11+U11)/2) -> 0
A12: 4 | B12: 19769700 | C12: BATRES ROMERO, VALERIA NICOLLE | D12: F | H12: =(E12+F12+G12)/3 -> 0 | I12: =H12*0.125 -> 0 | M12: =(J12+K12+L12)/3 -> 0 | N12: =M12*0.25 -> 0 | R12: =(O12+P12+Q12)/3 -> 0 | S12: =R12*0.125 -> 0 | T12: =(I12+N12+S12) -> 0 | V12: =IF(U12<=0,T12,(T12+U12)/2) -> 0
A13: 5 | B13: 19769732 | C13: BONILLA REYES, RUTH NOHEMY | D13: F | H13: =(E13+F13+G13)/3 -> 0 | I13: =H13*0.125 -> 0 | M13: =(J13+K13+L13)/3 -> 0 | N13: =M13*0.25 -> 0 | R13: =(O13+P13+Q13)/3 -> 0 | S13: =R13*0.125 -> 0 | T13: =(I13+N13+S13) -> 0 | V13: =IF(U13<=0,T13,(T13+U13)/2) -> 0
A14: 6 | B14: 19769682 | C14: CAÑAS PÉREZ, LESLY VALERIA | D14: F | H14: =(E14+F14+G14)/3 -> 0 | I14: =H14*0.125 -> 0 | M14: =(J14+K14+L14)/3 -> 0 | N14: =M14*0.25 -> 0 | R14: =(O14+P14+Q14)/3 -> 0 | S14: =R14*0.125 -> 0 | T14: =(I14+N14+S14) -> 0 | V14: =IF(U14<=0,T14,(T14+U14)/2) -> 0
A15: 7 | B15: 19913170 | C15: CHICAS FLORES, DANIEL ALEJANDRO | D15: M | H15: =(E15+F15+G15)/3 -> 0 | I15: =H15*0.125 -> 0 | M15: =(J15+K15+L15)/3 -> 0 | N15: =M15*0.25 -> 0 | R15: =(O15+P15+Q15)/3 -> 0 | S15: =R15*0.125 -> 0 | T15: =(I15+N15+S15) -> 0 | V15: =IF(U15<=0,T15,(T15+U15)/2) -> 0
A16: 8 | B16: 5059703 | C16: FLORES TURCIOS, CÉSAR ALEXANDER | D16: M | H16: =(E16+F16+G16)/3 -> 0 | I16: =H16*0.125 -> 0 | M16: =(J16+K16+L16)/3 -> 0 | N16: =M16*0.25 -> 0 | R16: =(O16+P16+Q16)/3 -> 0 | S16: =R16*0.125 -> 0 | T16: =(I16+N16+S16) -> 0 | V16: =IF(U16<=0,T16,(T16+U16)/2) -> 0
A17: 9 | B17: 19770269 | C17: FUENTES FUENTES, DIEGO SEBASTIÁN | D17: M | H17: =(E17+F17+G17)/3 -> 0 | I17: =H17*0.125 -> 0 | M17: =(J17+K17+L17)/3 -> 0 | N17: =M17*0.25 -> 0 | R17: =(O17+P17+Q17)/3 -> 0 | S17: =R17*0.125 -> 0 | T17: =(I17+N17+S17) -> 0 | V17: =IF(U17<=0,T17,(T17+U17)/2) -> 0
A18: 10 | B18: 20238015 | C18: FUNES RAMÍREZ, DAMARIS RAQUEL | D18: F | H18: =(E18+F18+G18)/3 -> 0 | I18: =H18*0.125 -> 0 | M18: =(J18+K18+L18)/3 -> 0 | N18: =M18*0.25 -> 0 | R18: =(O18+P18+Q18)/3 -> 0 | S18: =R18*0.125 -> 0 | T18: =(I18+N18+S18) -> 0 | V18: =IF(U18<=0,T18,(T18+U18)/2) -> 0
A19: 11 | B19: 19846395 | C19: GARCÍA HERNÁNDEZ, DANIEL ALEXANDER | D19: M | H19: =(E19+F19+G19)/3 -> 0 | I19: =H19*0.125 -> 0 | M19: =(J19+K19+L19)/3 -> 0 | N19: =M19*0.25 -> 0 | R19: =(O19+P19+Q19)/3 -> 0 | S19: =R19*0.125 -> 0 | T19: =(I19+N19+S19) -> 0 | V19: =IF(U19<=0,T19,(T19+U19)/2) -> 0
A20: 12 | B20: 19913145 | C20: GRANILLO FLORES, JEFFERSON ALEJANDRO | D20: M | H20: =(E20+F20+G20)/3 -> 0 | I20: =H20*0.125 -> 0 | M20: =(J20+K20+L20)/3 -> 0 | N20: =M20*0.25 -> 0 | R20: =(O20+P20+Q20)/3 -> 0 | S20: =R20*0.125 -> 0 | T20: =(I20+N20+S20) -> 0 | V20: =IF(U20<=0,T20,(T20+U20)/2) -> 0
... A36: 28 | B36: 19770033 | C36: ZELAYA BELTRÁN, JORGE ISMAEL | D36: M | H36: =(E36+F36+G36)/3 -> 0 | I36: =H36*0.125 -> 0 | M36: =(J36+K36+L36)/3 -> 0 | N36: =M36*0.25 -> 0 | R36: =(O36+P36+Q36)/3 -> 0 | S36: =R36*0.125 -> 0 | T36: =(I36+N36+S36) -> 0 | V36: =IF(U36<=0,T36,(T36+U36)/2) -> 0
A37: 29 | H37: =(E37+F37+G37)/3 -> 0 | I37: =H37*0.125 -> 0 | M37: =(J37+K37+L37)/3 -> 0 | N37: =M37*0.25 -> 0 | R37: =(O37+P37+Q37)/3 -> 0 | S37: =R37*0.125 -> 0 | T37: =(I37+N37+S37) -> 0 | V37: =IF(U37<=0,T37,(T37+U37)/2) -> 0
A38: 30 | H38: =(E38+F38+G38)/3 -> 0 | I38: =H38*0.125 -> 0 | M38: =(J38+K38+L38)/3 -> 0 | N38: =M38*0.25 -> 0 | R38: =(O38+P38+Q38)/3 -> 0 | S38: =R38*0.125 -> 0 | T38: =(I38+N38+S38) -> 0 | V38: =IF(U38<=0,T38,(T38+U38)/2) -> 0
A39: 31 | H39: =(E39+F39+G39)/3 -> 0 | I39: =H39*0.125 -> 0 | M39: =(J39+K39+L39)/3 -> 0 | N39: =M39*0.25 -> 0 | R39: =(O39+P39+Q39)/3 -> 0 | S39: =R39*0.125 -> 0 | T39: =(I39+N39+S39) -> 0 | V39: =IF(U39<=0,T39,(T39+U39)/2) -> 0
A40: 32 | H40: =(E40+F40+G40)/3 -> 0 | I40: =H40*0.125 -> 0 | M40: =(J40+K40+L40)/3 -> 0 | N40: =M40*0.25 -> 0 | R40: =(O40+P40+Q40)/3 -> 0 | S40: =R40*0.125 -> 0 | T40: =(I40+N40+S40) -> 0 | V40: =IF(U40<=0,T40,(T40+U40)/2) -> 0
A41: 33 | H41: =(E41+F41+G41)/3 -> 0 | I41: =H41*0.125 -> 0 | M41: =(J41+K41+L41)/3 -> 0 | N41: =M41*0.25 -> 0 | R41: =(O41+P41+Q41)/3 -> 0 | S41: =R41*0.125 -> 0 | T41: =(I41+N41+S41) -> 0 | V41: =IF(U41<=0,T41,(T41+U41)/2) -> 0
A42: 34 | H42: =(E42+F42+G42)/3 -> 0 | I42: =H42*0.125 -> 0 | M42: =(J42+K42+L42)/3 -> 0 | N42: =M42*0.25 -> 0 | R42: =(O42+P42+Q42)/3 -> 0 | S42: =R42*0.125 -> 0 | T42: =(I42+N42+S42) -> 0 | V42: =IF(U42<=0,T42,(T42+U42)/2) -> 0
A43: 35 | H43: =(E43+F43+G43)/3 -> 0 | I43: =H43*0.125 -> 0 | M43: =(J43+K43+L43)/3 -> 0 | N43: =M43*0.25 -> 0 | R43: =(O43+P43+Q43)/3 -> 0 | S43: =R43*0.125 -> 0 | T43: =(I43+N43+S43) -> 0 | V43: =IF(U43<=0,T43,(T43+U43)/2) -> 0
A44: 36 | H44: =(E44+F44+G44)/3 -> 0 | I44: =H44*0.125 -> 0 | M44: =(J44+K44+L44)/3 -> 0 | N44: =M44*0.25 -> 0 | R44: =(O44+P44+Q44)/3 -> 0 | S44: =R44*0.125 -> 0 | T44: =(I44+N44+S44) -> 0 | V44: =IF(U44<=0,T44,(T44+U44)/2) -> 0
A45: 37 | H45: =(E45+F45+G45)/3 -> 0 | I45: =H45*0.125 -> 0 | M45: =(J45+K45+L45)/3 -> 0 | N45: =M45*0.25 -> 0 | R45: =(O45+P45+Q45)/3 -> 0 | S45: =R45*0.125 -> 0 | T45: =(I45+N45+S45) -> 0 | V45: =IF(U45<=0,T45,(T45+U45)/2) -> 0
A46: 38 | H46: =(E46+F46+G46)/3 -> 0 | I46: =H46*0.125 -> 0 | M46: =(J46+K46+L46)/3 -> 0 | N46: =M46*0.25 -> 0 | R46: =(O46+P46+Q46)/3 -> 0 | S46: =R46*0.125 -> 0 | T46: =(I46+N46+S46) -> 0 | V46: =IF(U46<=0,T46,(T46+U46)/2) -> 0
A47: 39 | H47: =(E47+F47+G47)/3 -> 0 | I47: =H47*0.125 -> 0 | M47: =(J47+K47+L47)/3 -> 0 | N47: =M47*0.25 -> 0 | R47: =(O47+P47+Q47)/3 -> 0 | S47: =R47*0.125 -> 0 | T47: =(I47+N47+S47) -> 0 | V47: =IF(U47<=0,T47,(T47+U47)/2) -> 0
A48: 40 | H48: =(E48+F48+G48)/3 -> 0 | I48: =H48*0.125 -> 0 | M48: =(J48+K48+L48)/3 -> 0 | N48: =M48*0.25 -> 0 | R48: =(O48+P48+Q48)/3 -> 0 | S48: =R48*0.125 -> 0 | T48: =(I48+N48+S48) -> 0 | V48: =IF(U48<=0,T48,(T48+U48)/2) -> 0
... A57: 49 | H57: =(E57+F57+G57)/3 -> 0 | I57: =H57*0.125 -> 0 | M57: =(J57+K57+L57)/3 -> 0 | N57: =M57*0.25 -> 0 | R57: =(O57+P57+Q57)/3 -> 0 | S57: =R57*0.125 -> 0 | T57: =(I57+N57+S57) -> 0 | V57: =IF(U57<=0,T57,(T57+U57)/2) -> 0
